Workbook

Sheet Valores
C7: MODELO | D7: VALOR MENSAL | F7: MODELO | G7: VALOR MENSAL
C8: CONTAINER DOBRÁVEL | D8: 1000 | F8: POLO | G8: 4000
C9: CONTAINER BANHEIRO | D9: 1900 | F9: SAVEIRO | G9: 3900
F10: GERADOR | G10: 6500
F11: EMPILHADEIRA | G11: 9000
F12: TITANO | G12: 5500
F13: TRITON | G13: 6000
F14: AMBULÂNCIA | G14: 5000
F15: RETRO ESCAVADEIRA | G15: 13000
F16: ÔNIBUS 4X4 | G16: 16000
F17: ÔNIBUS | G17: 14000
F18: CAMINHÃO MUNCK | G18: 23000
F19: GUINDASTE | G19: 65000
F20: AMBULÂNCIA 4X4

Sheet Cobrança 02.2026
A1: FILIAL | B1: OS | C1: NOMECLATURA | D1: Nº FROTA | E1: TIPO DO VEICULO | F1: MODELO | G1: ANO | H1: PLACA/CHASSI | I1: MÊS | J1: INICIO | K1: FIM | L1: DIAS | M1: A COBRAR
A2: LOCADORA EXEMPLO LOCAÇÕES | B2: OS29764 | C2: VEICULO | D2: F8308 | E2: POLO | F2: Modelo Beta | G2: 2025 | H2: XRD-5505 | I2: 12 | J2: 46023 | K2: 46053 | L2: =K2 - J2 -> 30 | M2: =IF(L2=30, _xlfn.XLOOKUP(E2,Valores!$F$8:$F$20,Valores!$G$8:$G$20), (_xlfn.XLOOKUP(E2,Valores!$F$8:$F$20,Valores!$G$8:$G$20)/30)*L2 ) -> 4000
A3: LOCADORA EXEMPLO LOCAÇÕES | B3: OS73562 | C3: VEICULO | D3: F1072 | E3: POLO | F3: Modelo Beta | G3: 2024 | H3: BTR-1554 | I3: 12 | J3: 46023 | K3: 46053 | L3: =K3 - J3 -> 30 | M3: =IF(L3=30, _xlfn.XLOOKUP(E3,Valores!$F$8:$F$20,Valores!$G$8:$G$20), (_xlfn.XLOOKUP(E3,Valores!$F$8:$F$20,Valores!$G$8:$G$20)/30)*L3 ) -> 4000
A4: LOCADORA EXEMPLO LOCAÇÕES | B4: OS36300 | C4: MAQUINA | D4: F4553 | E4: EMPILHADEIRA | F4: Modelo Alpha | G4: 2025 | H4: BWP-5672 | I4: 12 | J4: 46023 | K4: 46053 | L4: =K4 - J4 -> 30 | M4: =IF(L4=30, _xlfn.XLOOKUP(E4,Valores!$F$8:$F$20,Valores!$G$8:$G$20), (_xlfn.XLOOKUP(E4,Valores!$F$8:$F$20,Valores!$G$8:$G$20)/30)*L4 ) -> 9000
A5: LOCADORA EXEMPLO LOCAÇÕES | B5: OS79928 | C5: VEICULO | D5: F8537 | E5: POLO | F5: Modelo Delta | G5: 2024 | H5: XPI-3031 | I5: 12 | J5: 46023 | K5: 46053 | L5: =K5 - J5 -> 30 | M5: =IF(L5=30, _xlfn.XLOOKUP(E5,Valores!$F$8:$F$20,Valores!$G$8:$G$20), (_xlfn.XLOOKUP(E5,Valores!$F$8:$F$20,Valores!$G$8:$G$20)/30)*L5 ) -> 4000
A6: LOCADORA EXEMPLO LOCAÇÕES | B6: OS26049 | C6: VEICULO | D6: F3737 | E6: POLO | F6: Modelo Gamma | G6: 2024 | H6: KMY-9061 | I6: 12 | J6: 46023 | K6: 46053 | L6: =K6 - J6 -> 30 | M6: =IF(L6=30, _xlfn.XLOOKUP(E6,Valores!$F$8:$F$20,Valores!$G$8:$G$20), (_xlfn.XLOOKUP(E6,Valores!$F$8:$F$20,Valores!$G$8:$G$20)/30)*L6 ) -> 4000
A7: LOCADORA EXEMPLO LOCAÇÕES | B7: OS64863 | C7: VEICULO | D7: F2118 | E7: AMBULÂNCIA | F7: Modelo Sigma | G7: 2022 | H7: WTH-0247 | I7: 12 | J7: 46023 | K7: 46053 | L7: =K7 - J7 -> 30 | M7: =IF(L7=30, _xlfn.XLOOKUP(E7,Valores!$F$8:$F$20,Valores!$G$8:$G$20), (_xlfn.XLOOKUP(E7,Valores!$F$8:$F$20,Valores!$G$8:$G$20)/30)*L7 ) -> 5000
A8: LOCADORA EXEMPLO LOCAÇÕES | B8: OS32874 | C8: VEICULO | D8: F7985 | E8: CAMINHÃO MUNCK | F8: Modelo Beta | G8: 2024 | H8: NYU-6998 | I8: 12 | J8: 46037 | K8: 46047 | L8: =K8 - J8 -> 10 | M8: =IF(L8=30, _xlfn.XLOOKUP(E8,Valores!$F$8:$F$20,Valores!$G$8:$G$20), (_xlfn.XLOOKUP(E8,Valores!$F$8:$F$20,Valores!$G$8:$G$20)/30)*L8 ) -> 7666.6667
A9: LOCADORA EXEMPLO LOCAÇÕES | B9: OS59793 | C9: EQUIPAMENTO | D9: F7379 | E9: GERADOR | F9: Modelo Sigma | H9: MHA-8161 | I9: 12 | J9: 46023 | K9: 46053 | L9: =K9 - J9 -> 30 | M9: =IF(L9=30, _xlfn.XLOOKUP(E9,Valores!$F$8:$F$20,Valores!$G$8:$G$20), (_xlfn.XLOOKUP(E9,Valores!$F$8:$F$20,Valores!$G$8:$G$20)/30)*L9 ) -> 6500
A10: LOCADORA EXEMPLO LOCAÇÕES | B10: OS84482 | C10: MAQUINA | D10: F9550 | E10: RETRO ESCAVADEIRA | F10: Modelo Alpha | G10: 2024 | H10: IZC-6711 | I10: 12 | J10: 46023 | K10: 46053 | L10: =K10 - J10 -> 30 | M10: =IF(L10=30, _xlfn.XLOOKUP(E10,Valores!$F$8:$F$20,Valores!$G$8:$G$20), (_xlfn.XLOOKUP(E10,Valores!$F$8:$F$20,Valores!$G$8:$G$20)/30)*L10 ) -> 13000
A11: LOCADORA EXEMPLO LOCAÇÕES | B11: OS40750 | C11: MAQUINA | D11: F9939 | E11: RETRO ESCAVADEIRA | F11: Modelo Sigma | G11: 2024 | H11: DJR-4951 | I11: 12 | J11: 46023 | K11: 46053 | L11: =K11 - J11 -> 30 | M11: =IF(L11=30, _xlfn.XLOOKUP(E11,Valores!$F$8:$F$20,Valores!$G$8:$G$20), (_xlfn.XLOOKUP(E11,Valores!$F$8:$F$20,Valores!$G$8:$G$20)/30)*L11 ) -> 13000
A12: LOCADORA EXEMPLO LOCAÇÕES | B12: OS43558 | C12: VEICULO | D12: F9036 | E12: SAVEIRO | F12: Modelo Sigma | G12: 2024 | H12: HAK-5342 | I12: 12 | J12: 46023 | K12: 46053 | L12: =K12 - J12 -> 30 | M12: =IF(L12=30, _xlfn.XLOOKUP(E12,Valores!$F$8:$F$20,Valores!$G$8:$G$20), (_xlfn.XLOOKUP(E12,Valores!$F$8:$F$20,Valores!$G$8:$G$20)/30)*L12 ) -> 3900
A13: LOCADORA EXEMPLO LOCAÇÕES | B13: OS63390 | C13: MAQUINA | D13: F9119 | E13: RETRO ESCAVADEIRA | F13: Modelo Gamma | G13: 2025 | H13: ADM-0270 | I13: 12 | J13: 46023 | K13: 46053 | L13: =K13 - J13 -> 30 | M13: =IF(L13=30, _xlfn.XLOOKUP(E13,Valores!$F$8:$F$20,Valores!$G$8:$G$20), (_xlfn.XLOOKUP(E13,Valores!$F$8:$F$20,Valores!$G$8:$G$20)/30)*L13 ) -> 13000
A14: LOCADORA EXEMPLO LOCAÇÕES | B14: OS41821 | C14: VEICULO | D14: F2495 | E14: TRITON | F14: Modelo Sigma | H14: TCS-9566 | I14: 12 | J14: 46023 | K14: 46053 | L14: =K14 - J14 -> 30 | M14: =IF(L14=30, _xlfn.XLOOKUP(E14,Valores!$F$8:$F$20,Valores!$G$8:$G$20), (_xlfn.XLOOKUP(E14,Valores!$F$8:$F$20,Valores!$G$8:$G$20)/30)*L14 ) -> 6000
A15: LOCADORA EXEMPLO LOCAÇÕES | B15: OS86889 | C15: VEICULO | D15: F3555 | E15: TITANO | F15: Modelo Sigma | G15: 2025 | H15: YWO-3501 | I15: 12 | J15: 46023 | K15: 46053 | L15: =K15 - J15 -> 30 | M15: =IF(L15=30, _xlfn.XLOOKUP(E15,Valores!$F$8:$F$20,Valores!$G$8:$G$20), (_xlfn.XLOOKUP(E15,Valores!$F$8:$F$20,Valores!$G$8:$G$20)/30)*L15 ) -> 5500
A16: LOCADORA EXEMPLO LOCAÇÕES | B16: OS77295 | C16: VEICULO | D16: F4764 | E16: POLO | F16: Modelo Delta | G16: 2025 | H16: NKZ-6535 | I16: 12 | J16: 46023 | K16: 46053 | L16: =K16 - J16 -> 30 | M16: =IF(L16=30, _xlfn.XLOOKUP(E16,Valores!$F$8:$F$20,Valores!$G$8:$G$20), (_xlfn.XLOOKUP(E16,Valores!$F$8:$F$20,Valores!$G$8:$G$20)/30)*L16 ) -> 4000
A17: LOCADORA EXEMPLO LOCAÇÕES | B17: OS79545 | C17: MAQUINA | D17: F2414 | E17: RETRO ESCAVADEIRA | F17: Modelo Alpha | G17: 2024 | H17: TBV-2447 | I17: 12 | J17: 46023 | K17: 46053 | L17: =K17 - J17 -> 30 | M17: =IF(L17=30, _xlfn.XLOOKUP(E17,Valores!$F$8:$F$20,Valores!$G$8:$G$20), (_xlfn.XLOOKUP(E17,Valores!$F$8:$F$20,Valores!$G$8:$G$20)/30)*L17 ) -> 13000
A18: LOCADORA EXEMPLO LOCAÇÕES | B18: OS20194 | C18: VEICULO | D18: F4667 | E18: SAVEIRO | F18: Modelo Gamma | G18: 2025 | H18: TKM-0114 | I18: 12 | J18: 46023 | K18: 46053 | L18: =K18 - J18 -> 30 | M18: =IF(L18=30, _xlfn.XLOOKUP(E18,Valores!$F$8:$F$20,Valores!$G$8:$G$20), (_xlfn.XLOOKUP(E18,Valores!$F$8:$F$20,Valores!$G$8:$G$20)/30)*L18 ) -> 3900
A19: LOCADORA EXEMPLO LOCAÇÕES | B19: OS92944 | C19: VEICULO | D19: F9224 | E19: SAVEIRO | F19: Modelo Gamma | G19: 2024 | H19: RYE-7021 | I19: 12 | J19: 46023 | K19: 46053 | L19: =K19 - J19 -> 30 | M19: =IF(L19=30, _xlfn.XLOOKUP(E19,Valores!$F$8:$F$20,Valores!$G$8:$G$20), (_xlfn.XLOOKUP(E19,Valores!$F$8:$F$20,Valores!$G$8:$G$20)/30)*L19 ) -> 3900
A20: LOCADORA EXEMPLO LOCAÇÕES | B20: OS94046 | C20: VEICULO | D20: F6173 | E20: ÔNIBUS 4X4 | F20: Modelo Delta | G20: 2022 | H20: TNC-2874 | I20: 12 | L20: =K20 - J20 -> 0 | M20: =IF(L20=30, _xlfn.XLOOKUP(E20,Valores!$F$8:$F$20,Valores!$G$8:$G$20), (_xlfn.XLOOKUP(E20,Valores!$F$8:$F$20,Valores!$G$8:$G$20)/30)*L20 ) -> 0
A21: LOCADORA EXEMPLO LOCAÇÕES | B21: OS80929 | C21: VEICULO | D21: F9243 | E21: SAVEIRO | F21: Modelo Beta | G21: 2024 | H21: LTA-3851 | I21: 12 | L21: =K21 - J21 -> 0 | M21: =IF(L21=30, _xlfn.XLOOKUP(E21,Valores!$F$8:$F$20,Valores!$G$8:$G$20), (_xlfn.XLOOKUP(E21,Valores!$F$8:$F$20,Valores!$G$8:$G$20)/30)*L21 ) -> 0
A22: LOCADORA EXEMPLO LOCAÇÕES | B22: OS68860 | C22: VEICULO | D22: F3017 | E22: GUINDASTE | F22: Modelo Gamma | G22: 2024 | H22: VDZ-4382 | I22: 12 | L22: =K22 - J22 -> 0 | M22: =IF(L22=30, _xlfn.XLOOKUP(E22,Valores!$F$8:$F$20,Valores!$G$8:$G$20), (_xlfn.XLOOKUP(E22,Valores!$F$8:$F$20,Valores!$G$8:$G$20)/30)*L22 ) -> 0
A23: LOCADORA EXEMPLO LOCAÇÕES | B23: OS49574 | C23: VEICULO | D23: F2219 | E23: ÔNIBUS | F23: Modelo Beta | G23: 2019 | H23: CCK-8709 | I23: 12 | L23: =K23 - J23 -> 0 | M23: =IF(L23=30, _xlfn.XLOOKUP(E23,Valores!$F$8:$F$20,Valores!$G$8:$G$20), (_xlfn.XLOOKUP(E23,Valores!$F$8:$F$20,Valores!$G$8:$G$20)/30)*L23 ) -> 0
A24: LOCADORA EXEMPLO LOCAÇÕES | B24: OS26681 | C24: VEICULO | D24: F3896 | E24: ÔNIBUS | F24: Modelo Alpha | G24: 2024 | H24: SSQ-3792 | I24: 12 | L24: =K24 - J24 -> 0 | M24: =IF(L24=30, _xlfn.XLOOKUP(E24,Valores!$F$8:$F$20,Valores!$G$8:$G$20), (_xlfn.XLOOKUP(E24,Valores!$F$8:$F$20,Valores!$G$8:$G$20)/30)*L24 ) -> 0
A25: LOCADORA EXEMPLO LOCAÇÕES | B25: OS78683 | C25: VEICULO | D25: F5643 | E25: ÔNIBUS | F25: Modelo Alpha | G25: 2019 | H25: MPA-3589 | I25: 12 | L25: =K25 - J25 -> 0 | M25: =IF(L25=30, _xlfn.XLOOKUP(E25,Valores!$F$8:$F$20,Valores!$G$8:$G$20), (_xlfn.XLOOKUP(E25,Valores!$F$8:$F$20,Valores!$G$8:$G$20)/30)*L25 ) -> 0
A26: LOCADORA EXEMPLO LOCAÇÕES | B26: OS37035 | C26: MAQUINA | D26: F9076 | E26: RETRO ESCAVADEIRA | F26: Modelo Gamma | G26: 2025 | H26: LVF-0019 | I26: 12 | L26: =K26 - J26 -> 0 | M26: =IF(L26=30, _xlfn.XLOOKUP(E26,Valores!$F$8:$F$20,Valores!$G$8:$G$20), (_xlfn.XLOOKUP(E26,Valores!$F$8:$F$20,Valores!$G$8:$G$20)/30)*L26 ) -> 0
A27: LOCADORA EXEMPLO LOCAÇÕES | B27: OS65823 | C27: VEICULO | D27: F1387 | E27: CAMINHÃO MUNCK | F27: Modelo Gamma | G27: 2024 | H27: YPC-4237 | I27: 12 | L27: =K27 - J27 -> 0 | M27: =IF(L27=30, _xlfn.XLOOKUP(E27,Valores!$F$8:$F$20,Valores!$G$8:$G$20), (_xlfn.XLOOKUP(E27,Valores!$F$8:$F$20,Valores!$G$8:$G$20)/30)*L27 ) -> 0
A28: LOCADORA EXEMPLO LOCAÇÕES | B28: OS37664 | C28: VEICULO | D28: F6962 | E28: ÔNIBUS | F28: Modelo Delta | G28: 2019 | H28: NQO-2870 | I28: 12 | L28: =K28 - J28 -> 0 | M28: =IF(L28=30, _xlfn.XLOOKUP(E28,Valores!$F$8:$F$20,Valores!$G$8:$G$20), (_xlfn.XLOOKUP(E28,Valores!$F$8:$F$20,Valores!$G$8:$G$20)/30)*L28 ) -> 0
A29: LOCADORA EXEMPLO LOCAÇÕES | B29: OS84240 | C29: VEICULO | D29: F1206 | E29: ÔNIBUS | F29: Modelo Beta | G29: 2019 | H29: ITX-7884 | I29: 12 | L29: =K29 - J29 -> 0 | M29: =IF(L29=30, _xlfn.XLOOKUP(E29,Valores!$F$8:$F$20,Valores!$G$8:$G$20), (_xlfn.XLOOKUP(E29,Valores!$F$8:$F$20,Valores!$G$8:$G$20)/30)*L29 ) -> 0
A30: LOCADORA EXEMPLO LOCAÇÕES | B30: OS41867 | C30: VEICULO | D30: F1692 | E30: SAVEIRO | F30: Modelo Sigma | G30: 2025 | H30: PUO-4007 | I30: 12 | L30: =K30 - J30 -> 0 | M30: =IF(L30=30, _xlfn.XLOOKUP(E30,Valores!$F$8:$F$20,Valores!$G$8:$G$20), (_xlfn.XLOOKUP(E30,Valores!$F$8:$F$20,Valores!$G$8:$G$20)/30)*L30 ) -> 0
A31: LOCADORA EXEMPLO LOCAÇÕES | B31: OS29733 | C31: VEICULO | D31: F4195 | E31: AMBULÂNCIA 4X4 | F31: Modelo Delta | G31: 2025 | H31: KLX-4569 | I31: 12 | L31: =K31 - J31 -> 0 | M31: =IF(L31=30, _xlfn.XLOOKUP(E31,Valores!$F$8:$F$20,Valores!$G$8:$G$20), (_xlfn.XLOOKUP(E31,Valores!$F$8:$F$20,Valores!$G$8:$G$20)/30)*L31 ) -> 0
A32: LOCADORA EXEMPLO LOCAÇÕES | B32: OS72977 | C32: CONTAINER | E32: CONTAINER BANHEIRO | F32: Modelo Gamma | H32: AME-7630 | I32: 12 | J32: 46023 | K32: 46053 | L32: =K32 - J32 -> 30 | M32: =IF(L32=30, _xlfn.XLOOKUP(E32,Valores!$C$8:$C$9,Valores!$D$8:$D$9), (_xlfn.XLOOKUP(E32,Valores!$C$8:$C$9,Valores!$D$8:$D$9)/30)*L32 ) -> 1900
A33: LOCADORA EXEMPLO LOCAÇÕES | B33: OS90855 | C33: CONTAINER | E33: CONTAINER BANHEIRO | F33: Modelo Sigma | H33: HGL-6091 | I33: 12 | J33: 46023 | K33: 46053 | L33: =K33 - J33 -> 30 | M33: =IF(L33=30, _xlfn.XLOOKUP(E33,Valores!$C$8:$C$9,Valores!$D$8:$D$9), (_xlfn.XLOOKUP(E33,Valores!$C$8:$C$9,Valores!$D$8:$D$9)/30)*L33 ) -> 1900
A34: LOCADORA EXEMPLO LOCAÇÕES | B34: OS54367 | C34: CONTAINER | E34: CONTAINER DOBRÁVEL | F34: Modelo Delta | H34: GLX-0158 | I34: 12 | J34: 46023 | K34: 46053 | L34: =K34 - J34 -> 30 | M34: =IF(L34=30, _xlfn.XLOOKUP(E34,Valores!$C$8:$C$9,Valores!$D$8:$D$9), (_xlfn.XLOOKUP(E34,Valores!$C$8:$C$9,Valores!$D$8:$D$9)/30)*L34 ) -> 1000
A35: LOCADORA EXEMPLO LOCAÇÕES | B35: OS81732 | C35: CONTAINER | E35: CONTAINER DOBRÁVEL | F35: Modelo Gamma | H35: ZFZ-0998 | I35: 12 | J35: 46023 | K35: 46053 | L35: =K35 - J35 -> 30 | M35: =IF(L35=30, _xlfn.XLOOKUP(E35,Valores!$C$8:$C$9,Valores!$D$8:$D$9), (_xlfn.XLOOKUP(E35,Valores!$C$8:$C$9,Valores!$D$8:$D$9)/30)*L35 ) -> 1000
A36: LOCADORA EXEMPLO LOCAÇÕES | B36: OS13361 | C36: CONTAINER | E36: CONTAINER DOBRÁVEL | F36: Modelo Alpha | H36: CYF-9328 | I36: 12 | J36: 46023 | K36: 46053 | L36: =K36 - J36 -> 30 | M36: =IF(L36=30, _xlfn.XLOOKUP(E36,Valores!$C$8:$C$9,Valores!$D$8:$D$9), (_xlfn.XLOOKUP(E36,Valores!$C$8:$C$9,Valores!$D$8:$D$9)/30)*L36 ) -> 1000
A37: LOCADORA EXEMPLO LOCAÇÕES | B37: OS18306 | C37: CONTAINER | E37: CONTAINER DOBRÁVEL | F37: Modelo Alpha | H37: AFX-0006 | I37: 12 | J37: 46023 | K37: 46053 | L37: =K37 - J37 -> 30 | M37: =IF(L37=30, _xlfn.XLOOKUP(E37,Valores!$C$8:$C$9,Valores!$D$8:$D$9), (_xlfn.XLOOKUP(E37,Valores!$C$8:$C$9,Valores!$D$8:$D$9)/30)*L37 ) -> 1000
A38: LOCADORA EXEMPLO LOCAÇÕES | B38: OS38747 | C38: CONTAINER | E38: CONTAINER DOBRÁVEL | F38: Modelo Sigma | H38: KTB-9351 | I38: 12 | L38: =K38 - J38 -> 0 | M38: =IF(L38=30, _xlfn.XLOOKUP(E38,Valores!$C$8:$C$9,Valores!$D$8:$D$9), (_xlfn.XLOOKUP(E38,Valores!$C$8:$C$9,Valores!$D$8:$D$9)/30)*L38 ) -> 0
A39: LOCADORA EXEMPLO LOCAÇÕES | B39: OS70372 | C39: CONTAINER | E39: CONTAINER DOBRÁVEL | F39: Modelo Alpha | H39: ESB-5622 | I39: 12 | L39: =K39 - J39 -> 0 | M39: =IF(L39=30, _xlfn.XLOOKUP(E39,Valores!$C$8:$C$9,Valores!$D$8:$D$9), (_xlfn.XLOOKUP(E39,Valores!$C$8:$C$9,Valores!$D$8:$D$9)/30)*L39 ) -> 0
A40: LOCADORA EXEMPLO LOCAÇÕES | B40: OS33758 | C40: CONTAINER | E40: CONTAINER DOBRÁVEL | F40: Modelo Sigma | H40: UWL-2924 | I40: 12 | L40: =K40 - J40 -> 0 | M40: =IF(L40=30, _xlfn.XLOOKUP(E40,Valores!$C$8:$C$9,Valores!$D$8:$D$9), (_xlfn.XLOOKUP(E40,Valores!$C$8:$C$9,Valores!$D$8:$D$9)/30)*L40 ) -> 0
...

Sheet Planilha1
B1: MÊS 05/2025
B4: FILIAL | C4: OS | D4: ITEM | E4: INICIO DE LOCAÇÃO | F4: TERMINO | G4: DIAS | H4: VALOR DIA | I4: VALOR MENSAL | J4: VALOR A COBRAR | K4: VALOR DE MERCADO
B5: LOCADORA EXEMPLO LOCAÇÕES DE EQUIPAMENTOS | C5: OS 989 | D5: CONTAINER DOBRAVEL | E5: 45778 | F5: 45808 | G5: =F5-E5 -> 30 | H5: =I5/30 -> 30 | I5: 900 | J5: =H5*G5 -> 900 | K5: 23000
B6: LOCADORA EXEMPLO LOCAÇÕES DE EQUIPAMENTOS | C6: OS 996 | D6: CONTAINER DOBRAVEL | E6: 45778 | F6: 45808 | G6: =F6-E6 -> 30 | H6: =I6/30 -> 30 | I6: 900 | J6: =H6*G6 -> 900 | K6: 23000
B7: LOCADORA EXEMPLO LOCAÇÕES DE EQUIPAMENTOS | C7: OS 990 | D7: CONTAINER DOBRAVEL | E7: 45778 | F7: 45808 | G7: =F7-E7 -> 30 | H7: =I7/30 -> 30 | I7: 900 | J7: =H7*G7 -> 900 | K7: 23000
B8: LOCADORA EXEMPLO LOCAÇÕES DE EQUIPAMENTOS | C8: OS 990 | D8: CONTAINER DOBRAVEL | E8: 45778 | F8: 45808 | G8: =F8-E8 -> 30 | H8: =I8/30 -> 30 | I8: 900 | J8: =H8*G8 -> 900 | K8: 23000
B9: LOCADORA EXEMPLO LOCAÇÕES DE EQUIPAMENTOS | C9: OS 990 | D9: CONTAINER DOBRAVEL | E9: 45778 | F9: 45808 | G9: =F9-E9 -> 30 | H9: =I9/30 -> 30 | I9: 900 | J9: =H9*G9 -> 900 | K9: 23000
B10: LOCADORA EXEMPLO LOCAÇÕES DE EQUIPAMENTOS | C10: OS 996 | D10: CONTAINER DOBRAVEL | E10: 45778 | F10: 45808 | G10: =F10-E10 -> 30 | H10: =I10/30 -> 30 | I10: 900 | J10: =H10*G10 -> 900 | K10: 23000
B11: LOCADORA EXEMPLO LOCAÇÕES DE EQUIPAMENTOS | C11: OS 996 | D11: CONTAINER DOBRAVEL | E11: 45778 | F11: 45808 | G11: =F11-E11 -> 30 | H11: =I11/30 -> 30 | I11: 900 | J11: =H11*G11 -> 900 | K11: 23000
B12: LOCADORA EXEMPLO LOCAÇÕES DE EQUIPAMENTOS | C12: OS 996 | D12: CONTAINER DOBRAVEL | E12: 45778 | F12: 45808 | G12: =F12-E12 -> 30 | H12: =I12/30 -> 30 | I12: 900 | J12: =H12*G12 -> 900 | K12: 23000
B13: LOCADORA EXEMPLO LOCAÇÕES DE EQUIPAMENTOS | C13: OS 996 | D13: CONTAINER DOBRAVEL | E13: 45778 | F13: 45808 | G13: =F13-E13 -> 30 | H13: =I13/30 -> 30 | I13: 900 | J13: =H13*G13 -> 900 | K13: 27500
B14: LOCADORA EXEMPLO LOCAÇÕES DE EQUIPAMENTOS | C14: OS 996 | D14: CONTAINER DOBRAVEL | E14: 45778 | F14: 45808 | G14: =F14-E14 -> 30 | H14: =I14/30 -> 30 | I14: 900 | J14: =H14*G14 -> 900 | K14: 27500
B15: LOCADORA EXEMPLO LOCAÇÕES DE EQUIPAMENTOS | C15: OS 996 | D15: CONTAINER DOBRAVEL | E15: 45778 | F15: 45808 | G15: =F15-E15 -> 30 | H15: =I15/30 -> 30 | I15: 900 | J15: =H15*G15 -> 900 | K15: 27500
B16: LOCADORA EXEMPLO LOCAÇÕES DE EQUIPAMENTOS | C16: OS 993 | D16: CONTAINER BANHEIRO | E16: 45778 | F16: 45808 | G16: =F16-E16 -> 30 | H16: =I16/30 -> 60 | I16: 1800 | J16: =H16*G16 -> 1800 | K16: 35308
B17: LOCADORA EXEMPLO LOCAÇÕES DE EQUIPAMENTOS | C17: OS 996 | D17: CONTAINER BANHEIRO | E17: 45789 | F17: 45808 | G17: =F17-E17 -> 19 | H17: =I17/30 -> 60 | I17: 1800 | J17: =H17*G17 -> 1140 | K17: 35308

Sheet CONT 02-2025
B1: MÊS 02/2025
B4: FILIAL | C4: OS | D4: ITEM | E4: INICIO DE LOCAÇÃO | F4: TERMINO | G4: DIAS | H4: VALOR DIA | I4: VALOR MENSAL | J4: VALOR A COBRAR | K4: VALOR DE MERCADO
B5: LOCADORA EXEMPLO LOCAÇÕES DE EQUIPAMENTOS | C5: OS 989 | D5: CONTAINER DOBRAVEL | E5: 45689 | F5: 45716 | G5: =F5-E5 -> 27 | H5: =I5/30 -> 30 | I5: 900 | J5: =H5*G5 -> 810 | K5: 23000
B6: LOCADORA EXEMPLO LOCAÇÕES DE EQUIPAMENTOS | C6: OS 989 | D6: CONTAINER DOBRAVEL | E6: 45689 | F6: 45707 | G6: =F6-E6 -> 18 | H6: =I6/30 -> 30 | I6: 900 | J6: =H6*G6 -> 540 | K6: 23000
B7: LOCADORA EXEMPLO LOCAÇÕES DE EQUIPAMENTOS | C7: OS 996 | D7: CONTAINER DOBRAVEL | E7: 45709 | F7: 45716 | G7: =F7-E7 -> 7 | H7: =I7/30 -> 30 | I7: 900 | J7: =H7*G7 -> 210 | K7: 23000
B8: LOCADORA EXEMPLO LOCAÇÕES DE EQUIPAMENTOS | C8: OS 990 | D8: CONTAINER DOBRAVEL | E8: 45689 | F8: 45716 | G8: =F8-E8 -> 27 | H8: =I8/30 -> 30 | I8: 900 | J8: =H8*G8 -> 810 | K8: 23000
B9: LOCADORA EXEMPLO LOCAÇÕES DE EQUIPAMENTOS | C9: OS 990 | D9: CONTAINER DOBRAVEL | E9: 45689 | F9: 45716 | G9: =F9-E9 -> 27 | H9: =I9/30 -> 30 | I9: 900 | J9: =H9*G9 -> 810 | K9: 23000
B10: LOCADORA EXEMPLO LOCAÇÕES DE EQUIPAMENTOS | C10: OS 990 | D10: CONTAINER DOBRAVEL | E10: 45689 | F10: 45716 | G10: =F10-E10 -> 27 | H10: =I10/30 -> 30 | I10: 900 | J10: =H10*G10 -> 810 | K10: 23000
B11: LOCADORA EXEMPLO LOCAÇÕES DE EQUIPAMENTOS | C11: OS 994 | D11: CONTAINER DOBRAVEL | E11: 45689 | F11: 45707 | G11: =F11-E11 -> 18 | H11: =I11/30 -> 30 | I11: 900 | J11: =H11*G11 -> 540 | K11: 23000
B12: LOCADORA EXEMPLO LOCAÇÕES DE EQUIPAMENTOS | C12: OS 996 | D12: CONTAINER DOBRAVEL | E12: 45709 | F12: 45716 | G12: =F12-E12 -> 7 | H12: =I12/30 -> 30 | I12: 900 | J12: =H12*G12 -> 210 | K12: 23000
B13: LOCADORA EXEMPLO LOCAÇÕES DE EQUIPAMENTOS | C13: OS 996 | D13: CONTAINER DOBRAVEL | E13: 45689 | F13: 45716 | G13: =F13-E13 -> 27 | H13: =I13/30 -> 30 | I13: 900 | J13: =H13*G13 -> 810 | K13: 23000
B14: LOCADORA EXEMPLO LOCAÇÕES DE EQUIPAMENTOS | C14: OS 996 | D14: CONTAINER DOBRAVEL | E14: 45689 | F14: 45716 | G14: =F14-E14 -> 27 | H14: =I14/30 -> 30 | I14: 900 | J14: =H14*G14 -> 810 | K14: 23000
B15: LOCADORA EXEMPLO LOCAÇÕES DE EQUIPAMENTOS | C15: OS 996 | D15: CONTAINER DOBRAVEL | E15: 45702 | F15: 45716 | G15: =F15-E15 -> 14 | H15: =I15/30 -> 30 | I15: 900 | J15: =H15*G15 -> 420 | K15: 27500
B16: LOCADORA EXEMPLO LOCAÇÕES DE EQUIPAMENTOS | C16: OS 996 | D16: CONTAINER DOBRAVEL | E16: 45702 | F16: 45716 | G16: =F16-E16 -> 14 | H16: =I16/30 -> 30 | I16: 900 | J16: =H16*G16 -> 420 | K16: 27500
B17: LOCADORA EXEMPLO LOCAÇÕES DE EQUIPAMENTOS | C17: OS 996 | D17: CONTAINER DOBRAVEL | E17: 45702 | F17: 45716 | G17: =F17-E17 -> 14 | H17: =I17/30 -> 30 | I17: 900 | J17: =H17*G17 -> 420 | K17: 27500

Sheet 02-2025
B1: MÊS 02/2025
B4: FILIAL | C4: OS | D4: Nº FROTA | E4: TIPO DO VEICULO | F4: MODELO | G4: PLACA/CHASSI | H4: INICIO DE LOCAÇÃO | I4: TERMINO | J4: DIAS | K4: HODOMETRO / HORIMETRO | L4: VALOR DIA | M4: VALOR MENSAL | N4: VALOR A COBRAR | O4: ANO FABRICAÇÃO | P4: VALOR DE MERCADO
B5: LOCADORA EXEMPLO LOCAÇÕES DE EQUIPAMENTOS | C5: OS 955 | D5: EEL1915 | E5: SAVEIRO | F5: VW/SAVEIRO CS RB MF | G5: SAQ-3H53 | H5: 45689 | I5: 45716 | J5: =I5-H5 -> 27 | L5: =M5/30 -> 126.66667 | M5: 3800 | N5: =J5*L5 -> 3420 | O5: 2024 | P5: 78992.11
B6: LOCADORA EXEMPLO LOCAÇÕES DE EQUIPAMENTOS | C6: OS 981 | D6: EEL1996 | E6: GUINDASTE | F6: CAMINHÃO GUINDASTE SANY 70T | H6: 45689 | I6: 45716 | J6: =I6-H6 -> 27 | L6: =M6/30 -> 2000 | M6: 60000 | N6: =J6*L6 -> 54000 | O6: 2024 | P6: 1742640
B7: LOCADORA EXEMPLO LOCAÇÕES DE EQUIPAMENTOS | C7: OS 981 | D7: EEL1894 | E7: POLO | F7: VW/POLO TRACK MA | G7: SBC-1G02 | H7: 45689 | I7: 45716 | J7: =I7-H7 -> 27 | L7: =M7/30 -> 100 | M7: 3000 | N7: =J7*L7 -> 2700 | O7: 2024 | P7: 77112.46
B8: LOCADORA EXEMPLO LOCAÇÕES DE EQUIPAMENTOS | C8: OS 981 | D8: EEL1916 | E8: RETRO ESCAVADEIRA | F8: RETRO 3CX TURBO | G8: S0R3CXTTER3423145 | H8: 45689 | I8: 45716 | J8: =I8-H8 -> 27 | L8: =M8/30 -> 400 | M8: 12000 | N8: =J8*L8 -> 10800 | O8: 2024 | P8: 439000
B9: LOCADORA EXEMPLO LOCAÇÕES DE EQUIPAMENTOS | C9: OS 981 | D9: EEL1917 | E9: RETRO ESCAVADEIRA | F9: RETRO 3CX TURBO | G9: S0R3CXTTLR3423076 | H9: 45689 | I9: 45716 | J9: =I9-H9 -> 27 | L9: =M9/30 -> 400 | M9: 12000 | N9: =J9*L9 -> 10800 | O9: 2024 | P9: 439000
B10: LOCADORA EXEMPLO LOCAÇÕES DE EQUIPAMENTOS | C10: OS 981 | D10: EEL1913 | E10: SAVEIRO | F10: VW/SAVEIRO CS RB MF | G10: SAQ-5C03 | H10: 45689 | I10: 45716 | J10: =I10-H10 -> 27 | L10: =M10/30 -> 126.66667 | M10: 3800 | N10: =J10*L10 -> 3420 | O10: 2024 | P10: 78992.11
B11: LOCADORA EXEMPLO LOCAÇÕES DE EQUIPAMENTOS | C11: OS 985 | D11: EEL1893 | E11: POLO | F11: VW/POLO TRACK MA | G11: SBB-4F12 | H11: 45689 | I11: 45695 | J11: =I11-H11 -> 6 | L11: =M11/30 -> 100 | M11: 3000 | N11: =J11*L11 -> 600 | O11: 2024 | P11: 77112.46
B12: LOCADORA EXEMPLO LOCAÇÕES DE EQUIPAMENTOS | C12: OS 993 | D12: EEL1893 | E12: POLO | F12: VW/POLO TRACK MA | G12: SBB-4F12 | H12: 45696 | I12: 45716 | J12: =I12-H12 -> 20 | L12: =M12/30 -> 100 | M12: 3000 | N12: =J12*L12 -> 2000 | O12: 2024 | P12: 77112.46
B13: LOCADORA EXEMPLO LOCAÇÕES DE EQUIPAMENTOS | C13: OS 990 | D13: EEL2006 | E13: ONIBUS | F13: VW/MPOLO TORINO U | G13: EQS-4J69 | H13: 45689 | I13: 45716 | J13: =I13-H13 -> 27 | L13: =M13/30 -> 600 | M13: 18000 | N13: =J13*L13 -> 16200 | O13: 2019 | P13: 520000
B14: LOCADORA EXEMPLO LOCAÇÕES DE EQUIPAMENTOS | C14: OS 990 | D14: EEL1890 | E14: POLO | F14: VW/POLO TRACK MA | G14: SBC-6F82 | H14: 45689 | I14: 45716 | J14: =I14-H14 -> 27 | L14: =M14/30 -> 100 | M14: 3000 | N14: =J14*L14 -> 2700 | O14: 2024 | P14: 77112.46
B15: LOCADORA EXEMPLO LOCAÇÕES DE EQUIPAMENTOS | C15: OS 996 | D15: EEL1918 | E15: RETRO ESCAVADEIRA | F15: RETRO 3CX TURBO | G15: S0R3CXTTER3423064 | H15: 45689 | I15: 45716 | J15: =I15-H15 -> 27 | L15: =M15/30 -> 400 | M15: 12000 | N15: =J15*L15 -> 10800 | O15: 2024 | P15: 439000
B16: LOCADORA EXEMPLO LOCAÇÕES DE EQUIPAMENTOS | C16: OS 996 | D16: EEL1914 | E16: SAVEIRO | F16: VW/SAVEIRO CS RB MF | G16: SAQ-6G03 | H16: 45689 | I16: 45716 | J16: =I16-H16 -> 27 | L16: =M16/30 -> 126.66667 | M16: 3800 | N16: =J16*L16 -> 3420 | O16: 2024 | P16: 78992.11
B17: LOCADORA EXEMPLO LOCAÇÕES DE EQUIPAMENTOS | C17: OS 990 | D17: EEL2071 | E17: ONIBUS | F17: VOLVO/MASCA GRANVIAMD U | G17: LMU-4E23 | H17: 45698 | I17: 45716 | J17: =I17-H17 -> 18 | L17: =M17/30 -> 600 | M17: 18000 | N17: =J17*L17 -> 10800 | O17: 2019 | P17: 469000
B18: LOCADORA EXEMPLO LOCAÇÕES DE EQUIPAMENTOS | C18: OS 990 | D18: EEL1953 | E18: CAMINHÃO MUNCK | F18: VW/26.260 CRM 6X2 | G18: TIH-3F79 | H18: 45698 | I18: 45716 | J18: =I18-H18 -> 18 | L18: =M18/30 -> 700 | M18: 21000 | N18: =J18*L18 -> 12600 | O18: 2024 | P18: 1018000
